Workbook
Name Owners: Lists!$A$2:$A$11
Name TaskStatus: Lists!$B$2:$B$7
Name Priority: Lists!$C$2:$C$4
Name PartnerType: Lists!$D$2:$D$7
Name Channel: Lists!$E$2:$E$10
Name PartnerStatus: Lists!$F$2:$F$10
Name YesNo: Lists!$G$2:$G$3
Name ContentChannel: Lists!$H$2:$H$9
Name ContentStatus: Lists!$I$2:$I$7
Name TestResult: Lists!$J$2:$J$5
Name Testers: Lists!$K$2:$K$6
Name PartnerOwners: Lists!$L$2:$L$3

Sheet Dashboard
A1: KolayXport Turkey: weekly dashboard (Phase 1 → 100 activated users)
A2: Targets come from docs/gtm/turkey-gameplan.md §4.8 (checkpoints W2/W4/W6/W8/W10; weeks in between interpolated). Contacts and partners count themselves from 'Partner pipeline'.
A3: Yellow cells = Merisa types the Friday numbers from /admin/partners (signups, activated, paying). Actual < 80% of target in a week that has ended turns red.
D4: Targets: blue = from the gameplan
A5: Week | B5: Starts | C5: Ends | D5: Contacts target | E5: Contacts actual | F5: Partners signed target | G5: Partners signed actual | H5: Partners active target | I5: Partners active actual | J5: Signups target | K5: Signups actual | L5: Activated target | M5: Activated actual | N5: Paying target | O5: Paying actual | P5: Note
A6: W1 | B6: 46321 | C6: =B6+6 | D6: 0 | E6: =IF(B6>TODAY(),"",COUNTIFS('Partner pipeline'!$J$5:$J$404,"<="&C6)) | F6: 0 | G6: =IF(B6>TODAY(),"",COUNTIFS('Partner pipeline'!$O$5:$O$404,"<="&C6)) | H6: 0 | I6: =IF(B6>TODAY(),"",COUNTIFS('Partner pipeline'!$R$5:$R$404,"<="&C6)) | J6: 0 | L6: 0 | N6: 0 | P6: Set-up week: shortlist, freelancer, tracking test
A7: W2 | B7: 46328 | C7: =B7+6 | D7: 40 | E7: =IF(B7>TODAY(),"",COUNTIFS('Partner pipeline'!$J$5:$J$404,"<="&C7)) | F7: 2 | G7: =IF(B7>TODAY(),"",COUNTIFS('Partner pipeline'!$O$5:$O$404,"<="&C7)) | H7: 1 | I7: =IF(B7>TODAY(),"",COUNTIFS('Partner pipeline'!$R$5:$R$404,"<="&C7)) | J7: 10 | L7: 5 | N7: 0
A8: W3 | B8: 46335 | C8: =B8+6 | D8: 95 | E8: =IF(B8>TODAY(),"",COUNTIFS('Partner pipeline'!$J$5:$J$404,"<="&C8)) | F8: 4 | G8: =IF(B8>TODAY(),"",COUNTIFS('Partner pipeline'!$O$5:$O$404,"<="&C8)) | H8: 2 | I8: =IF(B8>TODAY(),"",COUNTIFS('Partner pipeline'!$R$5:$R$404,"<="&C8)) | J8: 26 | L8: 14 | N8: 0
A9: W4 | B9: 46342 | C9: =B9+6 | D9: 150 | E9: =IF(B9>TODAY(),"",COUNTIFS('Partner pipeline'!$J$5:$J$404,"<="&C9)) | F9: 7 | G9: =IF(B9>TODAY(),"",COUNTIFS('Partner pipeline'!$O$5:$O$404,"<="&C9)) | H9: 4 | I9: =IF(B9>TODAY(),"",COUNTIFS('Partner pipeline'!$R$5:$R$404,"<="&C9)) | J9: 42 | L9: 23 | N9: 1 | P9: First live demo
A10: W5 | B10: 46349 | C10: =B10+6 | D10: 205 | E10: =IF(B10>TODAY(),"",COUNTIFS('Partner pipeline'!$J$5:$J$404,"<="&C10)) | F10: 10 | G10: =IF(B10>TODAY(),"",COUNTIFS('Partner pipeline'!$O$5:$O$404,"<="&C10)) | H10: 5 | I10: =IF(B10>TODAY(),"",COUNTIFS('Partner pipeline'!$R$5:$R$404,"<="&C10)) | J10: 63 | L10: 34 | N10: 2
A11: W6 | B11: 46356 | C11: =B11+6 | D11: 260 | E11: =IF(B11>TODAY(),"",COUNTIFS('Partner pipeline'!$J$5:$J$404,"<="&C11)) | F11: 12 | G11: =IF(B11>TODAY(),"",COUNTIFS('Partner pipeline'!$O$5:$O$404,"<="&C11)) | H11: 7 | I11: =IF(B11>TODAY(),"",COUNTIFS('Partner pipeline'!$R$5:$R$404,"<="&C11)) | J11: 85 | L11: 45 | N11: 3 | P11: GTM/GA4/Meta IDs due 30 Nov
A12: W7 | B12: 46363 | C12: =B12+6 | D12: 315 | E12: =IF(B12>TODAY(),"",COUNTIFS('Partner pipeline'!$J$5:$J$404,"<="&C12)) | F12: 15 | G12: =IF(B12>TODAY(),"",COUNTIFS('Partner pipeline'!$O$5:$O$404,"<="&C12)) | H12: 8 | I12: =IF(B12>TODAY(),"",COUNTIFS('Partner pipeline'!$R$5:$R$404,"<="&C12)) | J12: 107 | L12: 58 | N12: 4
A13: W8 | B13: 46370 | C13: =B13+6 | D13: 370 | E13: =IF(B13>TODAY(),"",COUNTIFS('Partner pipeline'!$J$5:$J$404,"<="&C13)) | F13: 18 | G13: =IF(B13>TODAY(),"",COUNTIFS('Partner pipeline'!$O$5:$O$404,"<="&C13)) | H13: 10 | I13: =IF(B13>TODAY(),"",COUNTIFS('Partner pipeline'!$R$5:$R$404,"<="&C13)) | J13: 130 | L13: 72 | N13: 5 | P13: Black Friday content via partners
A14: W9 | B14: 46377 | C14: =B14+6 | D14: 425 | E14: =IF(B14>TODAY(),"",COUNTIFS('Partner pipeline'!$J$5:$J$404,"<="&C14)) | F14: 20 | G14: =IF(B14>TODAY(),"",COUNTIFS('Partner pipeline'!$O$5:$O$404,"<="&C14)) | H14: 11 | I14: =IF(B14>TODAY(),"",COUNTIFS('Partner pipeline'!$R$5:$R$404,"<="&C14)) | J14: 152 | L14: 83 | N14: 7 | P14: Holiday weeks: light outreach
A15: W10 | B15: 46384 | C15: =B15+6 | D15: 480 | E15: =IF(B15>TODAY(),"",COUNTIFS('Partner pipeline'!$J$5:$J$404,"<="&C15)) | F15: 23 | G15: =IF(B15>TODAY(),"",COUNTIFS('Partner pipeline'!$O$5:$O$404,"<="&C15)) | H15: 13 | I15: =IF(B15>TODAY(),"",COUNTIFS('Partner pipeline'!$R$5:$R$404,"<="&C15)) | J15: 175 | L15: 95 | N15: 9
A16: W11 | B16: 46391 | C16: =B16+6 | D16: 535 | E16: =IF(B16>TODAY(),"",COUNTIFS('Partner pipeline'!$J$5:$J$404,"<="&C16)) | F16: 26 | G16: =IF(B16>TODAY(),"",COUNTIFS('Partner pipeline'!$O$5:$O$404,"<="&C16)) | H16: 14 | I16: =IF(B16>TODAY(),"",COUNTIFS('Partner pipeline'!$R$5:$R$404,"<="&C16)) | J16: 195 | L16: 100 | N16: 10 | P16: Gate review: 100 activated + ≥5 paying + tracking live
A17: W12 | B17: 46398 | C17: =B17+6 | D17: 590 | E17: =IF(B17>TODAY(),"",COUNTIFS('Partner pipeline'!$J$5:$J$404,"<="&C17)) | F17: 28 | G17: =IF(B17>TODAY(),"",COUNTIFS('Partner pipeline'!$O$5:$O$404,"<="&C17)) | H17: 15 | I17: =IF(B17>TODAY(),"",COUNTIFS('Partner pipeline'!$R$5:$R$404,"<="&C17)) | J17: 215 | L17: 110 | N17: 11 | P17: Phase 2 (if gate passed): Instagram, then Meta ads ₺15k
A18: W13 | B18: 46405 | C18: =B18+6 | D18: 645 | E18: =IF(B18>TODAY(),"",COUNTIFS('Partner pipeline'!$J$5:$J$404,"<="&C18)) | F18: 31 | G18: =IF(B18>TODAY(),"",COUNTIFS('Partner pipeline'!$O$5:$O$404,"<="&C18)) | H18: 16 | I18: =IF(B18>TODAY(),"",COUNTIFS('Partner pipeline'!$R$5:$R$404,"<="&C18)) | J18: 235 | L18: 120 | N18: 12
A21: Phase 2 gate (turkey-gameplan §4.9)
A22: Activated users ≥ 100 | E22: =IF(MAX(M6:M18)>=100,"MET","not yet ("&MAX(M6:M18)&")")
A23: Paying customers ≥ 5 | E23: =IF(MAX(O6:O18)>=5,"MET","not yet ("&MAX(O6:O18)&")")
A24: GTM / GA4 / Meta IDs live (task T10) | E24: =IF(INDEX(Tasks!E:E,MATCH("T10",Tasks!A:A,0))="Done","MET","not yet")
A25: Cookie panel live | E25: ="MET (since 2026-10-17)"
A26: Attribution stored on the user (task T24) | E26: =IF(INDEX(Tasks!E:E,MATCH("T24",Tasks!A:A,0))="Done","MET","not yet")
A29: Partner pipeline by status
A30: Shortlisted | C30: =COUNTIF('Partner pipeline'!$I$5:$I$404,A30)
A31: Contacted | C31: =COUNTIF('Partner pipeline'!$I$5:$I$404,A31)
A32: Replied | C32: =COUNTIF('Partner pipeline'!$I$5:$I$404,A32)
A33: Terms sent | C33: =COUNTIF('Partner pipeline'!$I$5:$I$404,A33)
A34: Signed | C34: =COUNTIF('Partner pipeline'!$I$5:$I$404,A34)
A35: Active | C35: =COUNTIF('Partner pipeline'!$I$5:$I$404,A35)
A36: Declined | C36: =COUNTIF('Partner pipeline'!$I$5:$I$404,A36)
A37: Opted out | C37: =COUNTIF('Partner pipeline'!$I$5:$I$404,A37)
A38: Paused | C38: =COUNTIF('Partner pipeline'!$I$5:$I$404,A38)
A39: Bounties pending ₺ | C39: =SUM('Partner pipeline'!$X$5:$X$404)
A40: Bounties paid ₺ | C40: =SUM('Partner pipeline'!$Y$5:$Y$404)
A41: Open tasks overdue | C41: =COUNTIF(Tasks!J:J,"OVERDUE")
A42: Tasks blocked | C42: =COUNTIF(Tasks!E:E,"Blocked")

Sheet Tasks
A1: Tasks
A2: Edit any row. Owner / Status / Priority are dropdowns. 'Overdue' fills itself; overdue rows turn red. Add new tasks at the bottom (copy the formula in column J).
A4: ID | B4: Task | C4: Owner | D4: Due | E4: Status | F4: Priority | G4: Link | H4: Depends on | I4: Notes | J4: Overdue?
A5: T01 | B5: Push the local docs commits to GitHub (git push origin main): gameplan, referral spec, pricing v2 | C5: Atilla | D5: 46315 | E5: Not started | F5: P0 | G5: https://github.com/bloodyteeths/kolayxport_supa/blob/main/docs/gtm/turkey-gameplan.md | I5: Session pushes are blocked by permissions; docs only | J5: =IF(AND(D5<>"",D5<TODAY(),E5<>"Done",E5<>"Cancelled"),"OVERDUE","")
A6: T02 | B6: Share this ERP sheet with Merisa and Ekin | C6: Atilla | D6: 46316 | E6: Not started | F6: P0 | H6: T01 | I6: Import the .xlsx into Google Sheets first | J6: =IF(AND(D6<>"",D6<TODAY(),E6<>"Done",E6<>"Cancelled"),"OVERDUE","")
A7: T03 | B7: Confirm Merisa's weekly hours (plan assumes ~20 h) | C7: Atilla | D7: 46319 | E7: Not started | F7: P1 | G7: https://github.com/bloodyteeths/kolayxport_supa/blob/main/docs/gtm/turkey-gameplan.md | I7: Ekin = ~15 h/week (decided 19 Oct) | J7: =IF(AND(D7<>"",D7<TODAY(),E7<>"Done",E7<>"Cancelled"),"OVERDUE","")
A8: T04 | B8: Phone-verify the YouTube channel (lifts upload cap, makes description links clickable) | C8: Atilla | D8: 46321 | E8: Not started | F8: P0 | G8: https://studio.youtube.com | J8: =IF(AND(D8<>"",D8<TODAY(),E8<>"Done",E8<>"Cancelled"),"OVERDUE","")
A9: T05 | B9: Confirm pricing v2 package prices (Başlangıç / Büyüme / Pro / Kurumsal, Aylık) | C9: Atilla | D9: 46321 | E9: Done | F9: P0 | G9: https://github.com/bloodyteeths/kolayxport_supa/blob/main/docs/gtm/pricing-v2.md | I9: Confirmed 19 Oct 19:48 via command board | J9: =IF(AND(D9<>"",D9<TODAY(),E9<>"Done",E9<>"Cancelled"),"OVERDUE","")
A10: T05b | B10: Confirm pricing v2 module prices (finance, arbitrage, photo studio, extra store/orders) | C10: Atilla | D10: 46326 | E10: Not started | F10: P1 | G10: https://github.com/bloodyteeths/kolayxport_supa/blob/main/docs/gtm/pricing-v2.md | I10: Still a proposal | J10: =IF(AND(D10<>"",D10<TODAY(),E10<>"Done",E10<>"Cancelled"),"OVERDUE","")
A11: T06 | B11: Take the 4 accountant questions (seller of record + KDV, partner payout paperwork, deductibility) | C11: Atilla | D11: 46326 | E11: Not started | F11: P0 | G11: https://github.com/bloodyteeths/kolayxport_supa/blob/main/docs/gtm/pricing-v2.md | I11: pricing-v2 §5. Decides iyzico/PayTR entity | J11: =IF(AND(D11<>"",D11<TODAY(),E11<>"Done",E11<>"Cancelled"),"OVERDUE","")
A12: T07 | B12: Accountant answers the 4 questions | C12: Accountant | D12: 46333 | E12: Waiting | F12: P0 | G12: https://github.com/bloodyteeths/kolayxport_supa/blob/main/docs/gtm/pricing-v2.md | H12: T06 | J12: =IF(AND(D12<>"",D12<TODAY(),E12<>"Done",E12<>"Cancelled"),"OVERDUE","")
A13: T08 | B13: OK to switch the tutorials Unlisted → Public | C13: Atilla | D13: 46328 | E13: Not started | F13: P1 | G13: https://studio.youtube.com | H13: T04 | J13: =IF(AND(D13<>"",D13<TODAY(),E13<>"Done",E13<>"Cancelled"),"OVERDUE","")
A14: T09 | B14: Create the Stripe partner coupon(s) and set STRIPE_PARTNER_COUPON_ID via stdin | C14: Atilla | D14: 46328 | E14: Not started | F14: P0 | G14: https://dashboard.stripe.com/coupons | I14: 20% once on yearly / repeating 3 months on Aylık | J14: =IF(AND(D14<>"",D14<TODAY(),E14<>"Done",E14<>"Cancelled"),"OVERDUE","")
A15: T10 | B15: Create GTM container + GA4 + Meta pixel IDs and set them in the Hetzner .env | C15: Atilla | D15: 46356 | E15: Not started | F15: P0 | G15: https://github.com/bloodyteeths/kolayxport_supa/blob/main/docs/gtm/tracking/README.md | I15: Phase 2 gate | J15: =IF(AND(D15<>"",D15<TODAY(),E15<>"Done",E15<>"Cancelled"),"OVERDUE","")
A16: T11 | B16: Enable Stripe Global Payouts on the Tamsar, Inc. account | C16: Atilla | D16: 46376 | E16: Not started | F16: P1 | G16: https://dashboard.stripe.com | H16: T07 | I16: Before the first payout run (5 Jan) | J16: =IF(AND(D16<>"",D16<TODAY(),E16<>"Done",E16<>"Cancelled"),"OVERDUE","")
A17: T12 | B17: Follow up Hepsiburada integrator ticket 1-404875606841365 | C17: Atilla | D17: 46316 | E17: Waiting | F17: P1 | I17: Planned close 21 Oct (Satıcı Paneli › Destek Kayıtlarım) | J17: =IF(AND(D17<>"",D17<TODAY(),E17<>"Done",E17<>"Cancelled"),"OVERDUE","")
A18: T13 | B18: Hire a Bionluk freelancer for list-building (120 groups + 60 X/YouTube) | C18: Merisa | D18: 46322 | E18: Not started | F18: P0 | G18: https://github.com/bloodyteeths/kolayxport_supa/blob/main/docs/gtm/turkey-gameplan.md | I18: Budget ₺4–6k; brief in gameplan §4.4 | J18: =IF(AND(D18<>"",D18<TODAY(),E18<>"Done",E18<>"Cancelled"),"OVERDUE","")
A19: T14 | B19: Shortlist + score 110 FB/Telegram groups and 20 müşavirler in Partner pipeline | C19: Merisa | D19: 46325 | E19: Not started | F19: P0 | H19: T13 | I19: Scoring rubric: gameplan §4.4 | J19: =IF(AND(D19<>"",D19<TODAY(),E19<>"Done",E19<>"Cancelled"),"OVERDUE","")
A20: T15 | B20: Shortlist + score 50 X accounts and 20 YouTube channels in Partner pipeline | C20: Ekin | D20: 46325 | E20: Not started | F20: P0 | J20: =IF(AND(D20<>"",D20<TODAY(),E20<>"Done",E20<>"Cancelled"),"OVERDUE","")
A21: T16 | B21: Week 1: 15 helpful answers in target groups (no links) | C21: Merisa | D21: 46325 | E21: Not started | F21: P1 | J21: =IF(AND(D21<>"",D21<TODAY(),E21<>"Done",E21<>"Cancelled"),"OVERDUE","")
A22: T17 | B22: Week 1: 15 helpful X replies on e-ihracat threads | C22: Ekin | D22: 46325 | E22: Not started | F22: P1 | J22: =IF(AND(D22<>"",D22<TODAY(),E22<>"Done",E22<>"Cancelled"),"OVERDUE","")
A23: T18 | B23: Manual prod check of referral Stage A: open /?ref=TEST-PARTNER, sign up, see 1 signup in /admin/partners, then delete test data | C23: Merisa | D23: 46319 | E23: Not started | F23: P0 | G23: https://kolayxport.com/admin/partners | I23: With Claude d7; see Tests Q01 | J23: =IF(AND(D23<>"",D23<TODAY(),E23<>"Done",E23<>"Cancelled"),"OVERDUE","")
A24: T19 | B24: Send the first partner messages (Varyant 5 / 6) | C24: Merisa | D24: 46328 | E24: Not started | F24: P0 | G24: https://github.com/bloodyteeths/kolayxport_supa/blob/main/docs/gtm/turkey-gameplan.md | H24: T09, T18 | I24: Only after tracking is confirmed | J24: =IF(AND(D24<>"",D24<TODAY(),E24<>"Done",E24<>"Cancelled"),"OVERDUE","")
A25: T20 | B25: Fact-check the blog posts (2 a week) | C25: Merisa | D25: 46329 | E25: Not started | F25: P1 | G25: https://github.com/bloodyteeths/kolayxport_supa/blob/main/docs/gtm/seo/content-calendar.md | I25: Recurring every Tue/Thu | J25: =IF(AND(D25<>"",D25<TODAY(),E25<>"Done",E25<>"Cancelled"),"OVERDUE","")
A26: T21 | B26: First live demo in a partner group (scripted, 30 min) | C26: Merisa | D26: 46344 | E26: Not started | F26: P1 | J26: =IF(AND(D26<>"",D26<TODAY(),E26<>"Done",E26<>"Cancelled"),"OVERDUE","")
A27: T22 | B27: Ask the first paying customers for written testimonial consent | C27: Merisa | D27: 46365 | E27: Not started | F27: P2 | G27: https://github.com/bloodyteeths/kolayxport_supa/blob/main/docs/gtm/social/legal-notes.md | J27: =IF(AND(D27<>"",D27<TODAY(),E27<>"Done",E27<>"Cancelled"),"OVERDUE","")
A28: T23 | B28: Phase 2: start Instagram organic (only if the gate passed) | C28: Ekin | D28: 46398 | E28: Not started | F28: P2 | G28: https://github.com/bloodyteeths/kolayxport_supa/blob/main/docs/gtm/social/calendar-30d.md | H28: Gate | J28: =IF(AND(D28<>"",D28<TODAY(),E28<>"Done",E28<>"Cancelled"),"OVERDUE","")
A29: T24 | B29: Referral Stage A (capture, claim, admin report) | C29: Claude: d7 (dev) | D29: 46314 | E29: Done | F29: P0 | G29: https://github.com/bloodyteeths/kolayxport_supa/blob/main/docs/gtm/referral-spec.md | I29: Deployed b6ee9895 | J29: =IF(AND(D29<>"",D29<TODAY(),E29<>"Done",E29<>"Cancelled"),"OVERDUE","")
A30: T25 | B30: Referral Stage B (bounty ledger, /app/ortaklik, Stripe Global Payouts) | C30: Claude: d7 (dev) | D30: 46333 | E30: In progress | F30: P0 | G30: https://github.com/bloodyteeths/kolayxport_supa/blob/main/docs/gtm/referral-spec.md | H30: T09 | I30: Spec §3–6 | J30: =IF(AND(D30<>"",D30<TODAY(),E30<>"Done",E30<>"Cancelled"),"OVERDUE","")
A31: T26 | B31: Pricing v2 P1: plan keys, yearly limits, modules | C31: Claude: to assign | D31: 46341 | E31: Not started | F31: P0 | G31: https://github.com/bloodyteeths/kolayxport_supa/blob/main/docs/gtm/pricing-v2.md | H31: T05b (modules only) | I31: Package prices decided; can start | J31: =IF(AND(D31<>"",D31<TODAY(),E31<>"Done",E31<>"Cancelled"),"OVERDUE","")
A32: T27 | B32: Pricing v2 P2: iyzico/PayTR yearly checkout with taksit | C32: Claude: to assign | D32: 46356 | E32: Blocked | F32: P0 | G32: https://github.com/bloodyteeths/kolayxport_supa/blob/main/docs/gtm/pricing-v2.md | H32: T07 | J32: =IF(AND(D32<>"",D32<TODAY(),E32<>"Done",E32<>"Cancelled"),"OVERDUE","")
A33: T28 | B33: Pricing v2 P4: /fiyatlandirma redesign | C33: Claude: gtm-overhaul | D33: 46356 | E33: Blocked | F33: P1 | G33: https://github.com/bloodyteeths/kolayxport_supa/blob/main/docs/gtm/pricing-v2.md | H33: T05, T07 | J33: =IF(AND(D33<>"",D33<TODAY(),E33<>"Done",E33<>"Cancelled"),"OVERDUE","")
A34: T29 | B34: Upload the remaining 8 tutorials | C34: Claude: gtm-overhaul | D34: 46315 | E34: In progress | F34: P1 | G34: https://studio.youtube.com | J34: =IF(AND(D34<>"",D34<TODAY(),E34<>"Done",E34<>"Cancelled"),"OVERDUE","")
A35: T30 | B35: Blog cadence: 2 posts a week from the content calendar | C35: Claude: gtm-overhaul | D35: 46329 | E35: Not started | F35: P1 | G35: https://github.com/bloodyteeths/kolayxport_supa/blob/main/docs/gtm/seo/content-calendar.md | H35: T20 | J35: =IF(AND(D35<>"",D35<TODAY(),E35<>"Done",E35<>"Cancelled"),"OVERDUE","")
A36: T31 | B36: Draft the /ortaklik partner-terms page (publish after Stage B + accountant) | C36: Claude: gtm-overhaul | D36: 46333 | E36: Not started | F36: P1 | G36: https://github.com/bloodyteeths/kolayxport_supa/blob/main/docs/gtm/turkey-gameplan.md | H36: T07, T25 | J36: =IF(AND(D36<>"",D36<TODAY(),E36<>"Done",E36<>"Cancelled"),"OVERDUE","")
A37: T32 | B37: Privacy notice: one line on masked referrals shown to partners | C37: Claude: gtm-overhaul | D37: 46333 | E37: Not started | F37: P1 | G37: https://github.com/bloodyteeths/kolayxport_supa/blob/main/docs/gtm/referral-spec.md | I37: Lawyer-review flag | J37: =IF(AND(D37<>"",D37<TODAY(),E37<>"Done",E37<>"Cancelled"),"OVERDUE","")
J38: =IF(AND(D38<>"",D38<TODAY(),E38<>"Done",E38<>"Cancelled"),"OVERDUE","")
J39: =IF(AND(D39<>"",D39<TODAY(),E39<>"Done",E39<>"Cancelled"),"OVERDUE","")
J40: =IF(AND(D40<>"",D40<TODAY(),E40<>"Done",E40<>"Cancelled"),"OVERDUE","")
J41: =IF(AND(D41<>"",D41<TODAY(),E41<>"Done",E41<>"Cancelled"),"OVERDUE","")
...

Sheet Partner pipeline
A1: Partner pipeline
A2: One row per admin / influencer / müşavir. Type, Channel, Owner, Status, Disclosure are dropdowns. Follow-up dates fill themselves (+4/+9/+16 days); 'Next action' turns amber when a follow-up is due. Signups → Bounty paid: copy from /admin/partners, never estimate.
A4: ID | B4: Name / group | C4: Type | D4: Channel | E4: Link | F4: Audience | G4: Score 0–10 | H4: Owner | I4: Status | J4: Date contacted | K4: Follow-up 1 | L4: Follow-up 2 | M4: Follow-up 3 | N4: Next action | O4: Date signed | P4: Ref code | Q4: Promo code | R4: First post date | S4: Post link | T4: Disclosure OK | U4: Signups | V4: Activated | W4: Paying | X4: Bounty pending ₺ | Y4: Bounty paid ₺ | Z4: Notes
A5: P001 | B5: Etsy ile Gelir | C5: tg_admin | D5: Telegram | E5: https://t.me/etsyilegelir | F5: 13102 | H5: Merisa | I5: Shortlisted | K5: =IF(J5="","",J5+4) | L5: =IF(J5="","",J5+9) | M5: =IF(J5="","",J5+16) | N5: =IF(OR(I5="Contacted",I5="Terms sent"),IF(TODAY()>=M5,"Close (step 3)",IF(TODAY()>=L5,"Follow-up 2",IF(TODAY()>=K5,"Follow-up 1",""))),IF(I5="Shortlisted",IF(G5="","Score it",""),"")) | Z5: From docs/gtm/social/communities.csv (verified 2026-10-17). Score before contacting.
A6: P002 | B6: Etsy Türkiye Grubu | C6: tg_admin | D6: Telegram | E6: https://t.me/etsyturkiyegrubu | F6: 2826 | H6: Merisa | I6: Shortlisted | K6: =IF(J6="","",J6+4) | L6: =IF(J6="","",J6+9) | M6: =IF(J6="","",J6+16) | N6: =IF(OR(I6="Contacted",I6="Terms sent"),IF(TODAY()>=M6,"Close (step 3)",IF(TODAY()>=L6,"Follow-up 2",IF(TODAY()>=K6,"Follow-up 1",""))),IF(I6="Shortlisted",IF(G6="","Score it",""),"")) | Z6: From docs/gtm/social/communities.csv (verified 2026-10-17). Score before contacting.
A7: P003 | B7: Etsy Türkiye Yardımlaşma Grubu | C7: tg_admin | D7: Telegram | E7: https://t.me/etsytr | F7: 1735 | H7: Merisa | I7: Shortlisted | K7: =IF(J7="","",J7+4) | L7: =IF(J7="","",J7+9) | M7: =IF(J7="","",J7+16) | N7: =IF(OR(I7="Contacted",I7="Terms sent"),IF(TODAY()>=M7,"Close (step 3)",IF(TODAY()>=L7,"Follow-up 2",IF(TODAY()>=K7,"Follow-up 1",""))),IF(I7="Shortlisted",IF(G7="","Score it",""),"")) | Z7: From docs/gtm/social/communities.csv (verified 2026-10-17). Score before contacting.
A8: P004 | B8: Ebay dropshipping TÜRKİYE | C8: tg_admin | D8: Telegram | E8: https://t.me/ebaydropshippingturkey | F8: 2352 | H8: Merisa | I8: Shortlisted | K8: =IF(J8="","",J8+4) | L8: =IF(J8="","",J8+9) | M8: =IF(J8="","",J8+16) | N8: =IF(OR(I8="Contacted",I8="Terms sent"),IF(TODAY()>=M8,"Close (step 3)",IF(TODAY()>=L8,"Follow-up 2",IF(TODAY()>=K8,"Follow-up 1",""))),IF(I8="Shortlisted",IF(G8="","Score it",""),"")) | Z8: From docs/gtm/social/communities.csv (verified 2026-10-17). Score before contacting.
A9: P005 | B9: Amazon & eBay Yardımlaşma Grubu | C9: tg_admin | D9: Telegram | E9: https://t.me/eBayveamazon | F9: 579 | H9: Merisa | I9: Shortlisted | K9: =IF(J9="","",J9+4) | L9: =IF(J9="","",J9+9) | M9: =IF(J9="","",J9+16) | N9: =IF(OR(I9="Contacted",I9="Terms sent"),IF(TODAY()>=M9,"Close (step 3)",IF(TODAY()>=L9,"Follow-up 2",IF(TODAY()>=K9,"Follow-up 1",""))),IF(I9="Shortlisted",IF(G9="","Score it",""),"")) | Z9: From docs/gtm/social/communities.csv (verified 2026-10-17). Score before contacting.
A10: P006 | B10: Etsy Türk Satıcıları (Etsy Community forumu) | C10: other | D10: Forum | E10: https://community.etsy.com/forum/etsy-t%C3%BCrk-sat%C4%B1c%C4%B1lar%C4%B1-95/ | H10: Merisa | I10: Shortlisted | K10: =IF(J10="","",J10+4) | L10: =IF(J10="","",J10+9) | M10: =IF(J10="","",J10+16) | N10: =IF(OR(I10="Contacted",I10="Terms sent"),IF(TODAY()>=M10,"Close (step 3)",IF(TODAY()>=L10,"Follow-up 2",IF(TODAY()>=K10,"Follow-up 1",""))),IF(I10="Shortlisted",IF(G10="","Score it",""),"")) | Z10: From docs/gtm/social/communities.csv (verified 2026-10-17). Score before contacting.
A11: P007 | B11: Etsy Türkiye Dijital ve POD | C11: other | D11: Forum | E11: https://community.etsy.com/etsy-turkiye-dijital-ve-pod/ | F11: 80 | H11: Merisa | I11: Shortlisted | K11: =IF(J11="","",J11+4) | L11: =IF(J11="","",J11+9) | M11: =IF(J11="","",J11+16) | N11: =IF(OR(I11="Contacted",I11="Terms sent"),IF(TODAY()>=M11,"Close (step 3)",IF(TODAY()>=L11,"Follow-up 2",IF(TODAY()>=K11,"Follow-up 1",""))),IF(I11="Shortlisted",IF(G11="","Score it",""),"")) | Z11: From docs/gtm/social/communities.csv (verified 2026-10-17). Score before contacting.
A12: P008 | B12: ETSY TÜRKİYE SATIŞ TEKNİKLERİ | C12: fb_admin | D12: Facebook | E12: https://www.facebook.com/groups/438314136353104/ | H12: Merisa | I12: Shortlisted | K12: =IF(J12="","",J12+4) | L12: =IF(J12="","",J12+9) | M12: =IF(J12="","",J12+16) | N12: =IF(OR(I12="Contacted",I12="Terms sent"),IF(TODAY()>=M12,"Close (step 3)",IF(TODAY()>=L12,"Follow-up 2",IF(TODAY()>=K12,"Follow-up 1",""))),IF(I12="Shortlisted",IF(G12="","Score it",""),"")) | Z12: From docs/gtm/social/communities.csv (verified 2026-10-17). Score before contacting.
A13: P009 | B13: etsytr (Facebook) | C13: fb_admin | D13: Facebook | E13: https://facebook.com/etsytr | H13: Merisa | I13: Shortlisted | K13: =IF(J13="","",J13+4) | L13: =IF(J13="","",J13+9) | M13: =IF(J13="","",J13+16) | N13: =IF(OR(I13="Contacted",I13="Terms sent"),IF(TODAY()>=M13,"Close (step 3)",IF(TODAY()>=L13,"Follow-up 2",IF(TODAY()>=K13,"Follow-up 1",""))),IF(I13="Shortlisted",IF(G13="","Score it",""),"")) | Z13: From docs/gtm/social/communities.csv (verified 2026-10-17). Score before contacting.
A14: P010 | B14: Mehmet TEK | C14: youtube | D14: YouTube | E14: https://www.youtube.com/@mehmettek | F14: 200000 | H14: Ekin | I14: Shortlisted | K14: =IF(J14="","",J14+4) | L14: =IF(J14="","",J14+9) | M14: =IF(J14="","",J14+16) | N14: =IF(OR(I14="Contacted",I14="Terms sent"),IF(TODAY()>=M14,"Close (step 3)",IF(TODAY()>=L14,"Follow-up 2",IF(TODAY()>=K14,"Follow-up 1",""))),IF(I14="Shortlisted",IF(G14="","Score it",""),"")) | Z14: From docs/gtm/social/communities.csv (verified 2026-10-17). Score before contacting.
A15: P011 | B15: Tuger Akkaya | C15: youtube | D15: YouTube | E15: https://www.youtube.com/@TugerAkkaya | F15: 662000 | H15: Ekin | I15: Shortlisted | K15: =IF(J15="","",J15+4) | L15: =IF(J15="","",J15+9) | M15: =IF(J15="","",J15+16) | N15: =IF(OR(I15="Contacted",I15="Terms sent"),IF(TODAY()>=M15,"Close (step 3)",IF(TODAY()>=L15,"Follow-up 2",IF(TODAY()>=K15,"Follow-up 1",""))),IF(I15="Shortlisted",IF(G15="","Score it",""),"")) | Z15: From docs/gtm/social/communities.csv (verified 2026-10-17). Score before contacting.
A16: P012 | B16: Canberk Ozturk | C16: youtube | D16: YouTube | E16: https://www.youtube.com/@canberkozturkk | F16: 109000 | H16: Ekin | I16: Shortlisted | K16: =IF(J16="","",J16+4) | L16: =IF(J16="","",J16+9) | M16: =IF(J16="","",J16+16) | N16: =IF(OR(I16="Contacted",I16="Terms sent"),IF(TODAY()>=M16,"Close (step 3)",IF(TODAY()>=L16,"Follow-up 2",IF(TODAY()>=K16,"Follow-up 1",""))),IF(I16="Shortlisted",IF(G16="","Score it",""),"")) | Z16: From docs/gtm/social/communities.csv (verified 2026-10-17). Score before contacting.
A17: P013 | B17: Hacı Mehmet KAYA | C17: youtube | D17: YouTube | E17: https://www.youtube.com/@HaciMehmetKAYA | F17: 35800 | H17: Ekin | I17: Shortlisted | K17: =IF(J17="","",J17+4) | L17: =IF(J17="","",J17+9) | M17: =IF(J17="","",J17+16) | N17: =IF(OR(I17="Contacted",I17="Terms sent"),IF(TODAY()>=M17,"Close (step 3)",IF(TODAY()>=L17,"Follow-up 2",IF(TODAY()>=K17,"Follow-up 1",""))),IF(I17="Shortlisted",IF(G17="","Score it",""),"")) | Z17: From docs/gtm/social/communities.csv (verified 2026-10-17). Score before contacting.
A18: P014 | B18: Muhammet USTA | C18: youtube | D18: YouTube | E18: https://www.youtube.com/@MuhammetUSTA | F18: 26300 | H18: Ekin | I18: Shortlisted | K18: =IF(J18="","",J18+4) | L18: =IF(J18="","",J18+9) | M18: =IF(J18="","",J18+16) | N18: =IF(OR(I18="Contacted",I18="Terms sent"),IF(TODAY()>=M18,"Close (step 3)",IF(TODAY()>=L18,"Follow-up 2",IF(TODAY()>=K18,"Follow-up 1",""))),IF(I18="Shortlisted",IF(G18="","Score it",""),"")) | Z18: From docs/gtm/social/communities.csv (verified 2026-10-17). Score before contacting.
A19: P015 | B19: podbul | C19: youtube | D19: YouTube | E19: https://www.youtube.com/@podbulsocial | F19: 12400 | H19: Ekin | I19: Shortlisted | K19: =IF(J19="","",J19+4) | L19: =IF(J19="","",J19+9) | M19: =IF(J19="","",J19+16) | N19: =IF(OR(I19="Contacted",I19="Terms sent"),IF(TODAY()>=M19,"Close (step 3)",IF(TODAY()>=L19,"Follow-up 2",IF(TODAY()>=K19,"Follow-up 1",""))),IF(I19="Shortlisted",IF(G19="","Score it",""),"")) | Z19: From docs/gtm/social/communities.csv (verified 2026-10-17). Score before contacting.
A20: P016 | B20: Veli Seferli | C20: youtube | D20: YouTube | E20: https://www.youtube.com/@veli.seferli | F20: 9100 | H20: Ekin | I20: Shortlisted | K20: =IF(J20="","",J20+4) | L20: =IF(J20="","",J20+9) | M20: =IF(J20="","",J20+16) | N20: =IF(OR(I20="Contacted",I20="Terms sent"),IF(TODAY()>=M20,"Close (step 3)",IF(TODAY()>=L20,"Follow-up 2",IF(TODAY()>=K20,"Follow-up 1",""))),IF(I20="Shortlisted",IF(G20="","Score it",""),"")) | Z20: From docs/gtm/social/communities.csv (verified 2026-10-17). Score before contacting.
A21: P017 | B21: BRMedya | C21: youtube | D21: YouTube | E21: https://www.youtube.com/@BRMedya | F21: 7910 | H21: Ekin | I21: Shortlisted | K21: =IF(J21="","",J21+4) | L21: =IF(J21="","",J21+9) | M21: =IF(J21="","",J21+16) | N21: =IF(OR(I21="Contacted",I21="Terms sent"),IF(TODAY()>=M21,"Close (step 3)",IF(TODAY()>=L21,"Follow-up 2",IF(TODAY()>=K21,"Follow-up 1",""))),IF(I21="Shortlisted",IF(G21="","Score it",""),"")) | Z21: From docs/gtm/social/communities.csv (verified 2026-10-17). Score before contacting.
A22: P018 | B22: Babal Mali Müşavirlik | C22: musavir | D22: YouTube | E22: https://www.youtube.com/@BabalMaliM%C3%BC%C5%9Favirlik | F22: 4470 | H22: Ekin | I22: Shortlisted | K22: =IF(J22="","",J22+4) | L22: =IF(J22="","",J22+9) | M22: =IF(J22="","",J22+16) | N22: =IF(OR(I22="Contacted",I22="Terms sent"),IF(TODAY()>=M22,"Close (step 3)",IF(TODAY()>=L22,"Follow-up 2",IF(TODAY()>=K22,"Follow-up 1",""))),IF(I22="Shortlisted",IF(G22="","Score it",""),"")) | Z22: From docs/gtm/social/communities.csv (verified 2026-10-17). Score before contacting.
A23: P019 | B23: E-Ticaret Adamı | C23: youtube | D23: YouTube | E23: https://www.youtube.com/@eticaretadami | F23: 2110 | H23: Ekin | I23: Shortlisted | K23: =IF(J23="","",J23+4) | L23: =IF(J23="","",J23+9) | M23: =IF(J23="","",J23+16) | N23: =IF(OR(I23="Contacted",I23="Terms sent"),IF(TODAY()>=M23,"Close (step 3)",IF(TODAY()>=L23,"Follow-up 2",IF(TODAY()>=K23,"Follow-up 1",""))),IF(I23="Shortlisted",IF(G23="","Score it",""),"")) | Z23: From docs/gtm/social/communities.csv (verified 2026-10-17). Score before contacting.
A24: P020 | B24: E-İhracat Akademisi (ShipEntegra) | C24: youtube | D24: YouTube | E24: https://www.youtube.com/@shipentegra | F24: 2760 | H24: Ekin | I24: Shortlisted | K24: =IF(J24="","",J24+4) | L24: =IF(J24="","",J24+9) | M24: =IF(J24="","",J24+16) | N24: =IF(OR(I24="Contacted",I24="Terms sent"),IF(TODAY()>=M24,"Close (step 3)",IF(TODAY()>=L24,"Follow-up 2",IF(TODAY()>=K24,"Follow-up 1",""))),IF(I24="Shortlisted",IF(G24="","Score it",""),"")) | Z24: From docs/gtm/social/communities.csv (verified 2026-10-17). Score before contacting.
A25: P021 | B25: E-Aramızda (bülten) | C25: other | D25: Substack | E25: https://gkhantanrverdi.substack.com | H25: Merisa | I25: Shortlisted | K25: =IF(J25="","",J25+4) | L25: =IF(J25="","",J25+9) | M25: =IF(J25="","",J25+16) | N25: =IF(OR(I25="Contacted",I25="Terms sent"),IF(TODAY()>=M25,"Close (step 3)",IF(TODAY()>=L25,"Follow-up 2",IF(TODAY()>=K25,"Follow-up 1",""))),IF(I25="Shortlisted",IF(G25="","Score it",""),"")) | Z25: From docs/gtm/social/communities.csv (verified 2026-10-17). Score before contacting.
A26: P022 | B26: Sıfırdan Globale (bülten) | C26: other | D26: Substack | E26: https://sifirdanglobale.substack.com | F26: 665 | H26: Merisa | I26: Shortlisted | K26: =IF(J26="","",J26+4) | L26: =IF(J26="","",J26+9) | M26: =IF(J26="","",J26+16) | N26: =IF(OR(I26="Contacted",I26="Terms sent"),IF(TODAY()>=M26,"Close (step 3)",IF(TODAY()>=L26,"Follow-up 2",IF(TODAY()>=K26,"Follow-up 1",""))),IF(I26="Shortlisted",IF(G26="","Score it",""),"")) | Z26: From docs/gtm/social/communities.csv (verified 2026-10-17). Score before contacting.
K27: =IF(J27="","",J27+4) | L27: =IF(J27="","",J27+9) | M27: =IF(J27="","",J27+16) | N27: =IF(OR(I27="Contacted",I27="Terms sent"),IF(TODAY()>=M27,"Close (step 3)",IF(TODAY()>=L27,"Follow-up 2",IF(TODAY()>=K27,"Follow-up 1",""))),IF(I27="Shortlisted",IF(G27="","Score it",""),""))
K28: =IF(J28="","",J28+4) | L28: =IF(J28="","",J28+9) | M28: =IF(J28="","",J28+16) | N28: =IF(OR(I28="Contacted",I28="Terms sent"),IF(TODAY()>=M28,"Close (step 3)",IF(TODAY()>=L28,"Follow-up 2",IF(TODAY()>=K28,"Follow-up 1",""))),IF(I28="Shortlisted",IF(G28="","Score it",""),""))
K29: =IF(J29="","",J29+4) | L29: =IF(J29="","",J29+9) | M29: =IF(J29="","",J29+16) | N29: =IF(OR(I29="Contacted",I29="Terms sent"),IF(TODAY()>=M29,"Close (step 3)",IF(TODAY()>=L29,"Follow-up 2",IF(TODAY()>=K29,"Follow-up 1",""))),IF(I29="Shortlisted",IF(G29="","Score it",""),""))
K30: =IF(J30="","",J30+4) | L30: =IF(J30="","",J30+9) | M30: =IF(J30="","",J30+16) | N30: =IF(OR(I30="Contacted",I30="Terms sent"),IF(TODAY()>=M30,"Close (step 3)",IF(TODAY()>=L30,"Follow-up 2",IF(TODAY()>=K30,"Follow-up 1",""))),IF(I30="Shortlisted",IF(G30="","Score it",""),""))
K31: =IF(J31="","",J31+4) | L31: =IF(J31="","",J31+9) | M31: =IF(J31="","",J31+16) | N31: =IF(OR(I31="Contacted",I31="Terms sent"),IF(TODAY()>=M31,"Close (step 3)",IF(TODAY()>=L31,"Follow-up 2",IF(TODAY()>=K31,"Follow-up 1",""))),IF(I31="Shortlisted",IF(G31="","Score it",""),""))
K32: =IF(J32="","",J32+4) | L32: =IF(J32="","",J32+9) | M32: =IF(J32="","",J32+16) | N32: =IF(OR(I32="Contacted",I32="Terms sent"),IF(TODAY()>=M32,"Close (step 3)",IF(TODAY()>=L32,"Follow-up 2",IF(TODAY()>=K32,"Follow-up 1",""))),IF(I32="Shortlisted",IF(G32="","Score it",""),""))
K33: =IF(J33="","",J33+4) | L33: =IF(J33="","",J33+9) | M33: =IF(J33="","",J33+16) | N33: =IF(OR(I33="Contacted",I33="Terms sent"),IF(TODAY()>=M33,"Close (step 3)",IF(TODAY()>=L33,"Follow-up 2",IF(TODAY()>=K33,"Follow-up 1",""))),IF(I33="Shortlisted",IF(G33="","Score it",""),""))
K34: =IF(J34="","",J34+4) | L34: =IF(J34="","",J34+9) | M34: =IF(J34="","",J34+16) | N34: =IF(OR(I34="Contacted",I34="Terms sent"),IF(TODAY()>=M34,"Close (step 3)",IF(TODAY()>=L34,"Follow-up 2",IF(TODAY()>=K34,"Follow-up 1",""))),IF(I34="Shortlisted",IF(G34="","Score it",""),""))
K35: =IF(J35="","",J35+4) | L35: =IF(J35="","",J35+9) | M35: =IF(J35="","",J35+16) | N35: =IF(OR(I35="Contacted",I35="Terms sent"),IF(TODAY()>=M35,"Close (step 3)",IF(TODAY()>=L35,"Follow-up 2",IF(TODAY()>=K35,"Follow-up 1",""))),IF(I35="Shortlisted",IF(G35="","Score it",""),""))
K36: =IF(J36="","",J36+4) | L36: =IF(J36="","",J36+9) | M36: =IF(J36="","",J36+16) | N36: =IF(OR(I36="Contacted",I36="Terms sent"),IF(TODAY()>=M36,"Close (step 3)",IF(TODAY()>=L36,"Follow-up 2",IF(TODAY()>=K36,"Follow-up 1",""))),IF(I36="Shortlisted",IF(G36="","Score it",""),""))
K37: =IF(J37="","",J37+4) | L37: =IF(J37="","",J37+9) | M37: =IF(J37="","",J37+16) | N37: =IF(OR(I37="Contacted",I37="Terms sent"),IF(TODAY()>=M37,"Close (step 3)",IF(TODAY()>=L37,"Follow-up 2",IF(TODAY()>=K37,"Follow-up 1",""))),IF(I37="Shortlisted",IF(G37="","Score it",""),""))
K38: =IF(J38="","",J38+4) | L38: =IF(J38="","",J38+9) | M38: =IF(J38="","",J38+16) | N38: =IF(OR(I38="Contacted",I38="Terms sent"),IF(TODAY()>=M38,"Close (step 3)",IF(TODAY()>=L38,"Follow-up 2",IF(TODAY()>=K38,"Follow-up 1",""))),IF(I38="Shortlisted",IF(G38="","Score it",""),""))
... K404: =IF(J404="","",J404+4) | L404: =IF(J404="","",J404+9) | M404: =IF(J404="","",J404+16) | N404: =IF(OR(I404="Contacted",I404="Terms sent"),IF(TODAY()>=M404,"Close (step 3)",IF(TODAY()>=L404,"Follow-up 2",IF(TODAY()>=K404,"Follow-up 1",""))),IF(I404="Shortlisted",IF(G404="","Score it",""),""))

Sheet Weekly plan
A1: Weekly plan per person (from turkey-gameplan.md §4.7 and §6)
A2: Read-only plan. Change it here only when the gameplan changes. Merisa ~20 h/week, Ekin ~15 h/week on KolayXport.
A4: Week | B4: Starts | C4: Person | D4: Focus | E4: Targets this week | F4: Key tasks
A5: W1 | B5: 46321 | C5: Merisa | D5: Set-up | E5: Shortlist 130 scored (110 groups + 20 müşavirler); 15 helpful answers | F5: Hire Bionluk freelancer (T13); score shortlist (T14); test Stage A tracking with d7 (T18). Daily ~4 h Mon–Fri: 5 helpful answers in groups (no links), 8 new admin messages (Varyant 5), follow-ups due, partner questions, check partner posts for #işbirliği.
A6: W1 | B6: 46321 | C6: Ekin | D6: Set-up | E6: Shortlist 70 scored (50 X + 20 YouTube); 15 X replies | F6: Score shortlist (T15); collect tutorial clips for Shorts. Daily ~3 h Mon–Fri: 3 X replies/quotes, 3 new messages (Varyant 6), 2 Shorts/clips a week from tutorials.
A7: W1 | B7: 46321 | C7: Weekly | D7: Mon: pick contacts · Fri: KPI report (Dashboard) to orchestrator | F7: Merisa fills Dashboard yellow cells on Friday from /admin/partners.
A8: W2 | B8: 46328 | C8: Merisa | D8: Outreach starts | E8: 30 contacts; 1–2 partners | F8: First Varyant 5 messages (after T09 + T18). Fact-check 2 blog posts. Daily ~4 h Mon–Fri: 5 helpful answers in groups (no links), 8 new admin messages (Varyant 5), follow-ups due, partner questions, check partner posts for #işbirliği.
A9: W2 | B9: 46328 | C9: Ekin | D9: Outreach starts | E9: 10 contacts; 0–1 partner | F9: First Varyant 6 messages. Tutorials go Public (T08). Daily ~3 h Mon–Fri: 3 X replies/quotes, 3 new messages (Varyant 6), 2 Shorts/clips a week from tutorials.
A10: W2 | B10: 46328 | C10: Weekly | D10: Mon: pick contacts · Fri: KPI report (Dashboard) to orchestrator | F10: Merisa fills Dashboard yellow cells on Friday from /admin/partners.
A11: W3 | B11: 46335 | C11: Merisa | D11: Outreach | E11: 40 contacts; first partner posts | F11: Send ready post drafts to signed partners. Daily ~4 h Mon–Fri: 5 helpful answers in groups (no links), 8 new admin messages (Varyant 5), follow-ups due, partner questions, check partner posts for #işbirliği.
A12: W3 | B12: 46335 | C12: Ekin | D12: Outreach | E12: 15 contacts | F12: Clips from public tutorials. Daily ~3 h Mon–Fri: 3 X replies/quotes, 3 new messages (Varyant 6), 2 Shorts/clips a week from tutorials.
A13: W3 | B13: 46335 | C13: Weekly | D13: Mon: pick contacts · Fri: KPI report (Dashboard) to orchestrator | F13: Merisa fills Dashboard yellow cells on Friday from /admin/partners.
A14: W4 | B14: 46342 | C14: Merisa | D14: Outreach + demo | E14: 40 contacts; 7 partners total; first live demo | F14: Run first live demo in a partner group (T21). Review reply/accept rates. Daily ~4 h Mon–Fri: 5 helpful answers in groups (no links), 8 new admin messages (Varyant 5), follow-ups due, partner questions, check partner posts for #işbirliği.
A15: W4 | B15: 46342 | C15: Ekin | D15: Outreach + demo | E15: 15 contacts | F15: Prepare demo screens from the demo account. Daily ~3 h Mon–Fri: 3 X replies/quotes, 3 new messages (Varyant 6), 2 Shorts/clips a week from tutorials.
A16: W4 | B16: 46342 | C16: Weekly | D16: Mon: pick contacts · Fri: KPI report (Dashboard) to orchestrator | F16: Merisa fills Dashboard yellow cells on Friday from /admin/partners.
A17: W5 | B17: 46349 | C17: Merisa | D17: Black Friday angle | E17: 40 contacts | F17: Partners share Black Friday content (blog #1, #7). Daily ~4 h Mon–Fri: 5 helpful answers in groups (no links), 8 new admin messages (Varyant 5), follow-ups due, partner questions, check partner posts for #işbirliği.
A18: W5 | B18: 46349 | C18: Ekin | D18: Black Friday angle | E18: 15 contacts | F18: Black Friday clips. Daily ~3 h Mon–Fri: 3 X replies/quotes, 3 new messages (Varyant 6), 2 Shorts/clips a week from tutorials.
A19: W5 | B19: 46349 | C19: Weekly | D19: Mon: pick contacts · Fri: KPI report (Dashboard) to orchestrator | F19: Merisa fills Dashboard yellow cells on Friday from /admin/partners.
A20: W6 | B20: 46356 | C20: Merisa | D20: Outreach | E20: 40 contacts; 12 partners total; 45 activated | F20: First trial→paid read. Chase T10 (tracking IDs due 30 Nov). Daily ~4 h Mon–Fri: 5 helpful answers in groups (no links), 8 new admin messages (Varyant 5), follow-ups due, partner questions, check partner posts for #işbirliği.
A21: W6 | B21: 46356 | C21: Ekin | D21: Outreach | E21: 15 contacts | F21: Daily ~3 h Mon–Fri: 3 X replies/quotes, 3 new messages (Varyant 6), 2 Shorts/clips a week from tutorials.
A22: W6 | B22: 46356 | C22: Weekly | D22: Mon: pick contacts · Fri: KPI report (Dashboard) to orchestrator | F22: Merisa fills Dashboard yellow cells on Friday from /admin/partners.
A23: W7 | B23: 46363 | C23: Merisa | D23: Second demo | E23: 40 contacts | F23: Second live demo. Ask first paying customers for testimonial consent (T22). Daily ~4 h Mon–Fri: 5 helpful answers in groups (no links), 8 new admin messages (Varyant 5), follow-ups due, partner questions, check partner posts for #işbirliği.
A24: W7 | B24: 46363 | C24: Ekin | D24: Outreach | E24: 15 contacts | F24: Daily ~3 h Mon–Fri: 3 X replies/quotes, 3 new messages (Varyant 6), 2 Shorts/clips a week from tutorials.
A25: W7 | B25: 46363 | C25: Weekly | D25: Mon: pick contacts · Fri: KPI report (Dashboard) to orchestrator | F25: Merisa fills Dashboard yellow cells on Friday from /admin/partners.
A26: W8 | B26: 46370 | C26: Merisa | D26: Outreach | E26: 40 contacts; 18 partners total; 72 activated | F26: Daily ~4 h Mon–Fri: 5 helpful answers in groups (no links), 8 new admin messages (Varyant 5), follow-ups due, partner questions, check partner posts for #işbirliği.
A27: W8 | B27: 46370 | C27: Ekin | D27: Outreach | E27: 15 contacts | F27: Daily ~3 h Mon–Fri: 3 X replies/quotes, 3 new messages (Varyant 6), 2 Shorts/clips a week from tutorials.
A28: W8 | B28: 46370 | C28: Weekly | D28: Mon: pick contacts · Fri: KPI report (Dashboard) to orchestrator | F28: Merisa fills Dashboard yellow cells on Friday from /admin/partners.
A29: W9 | B29: 46377 | C29: Merisa | D29: Holiday, light | E29: 20 contacts | F29: Focus on onboarding new users. Daily ~4 h Mon–Fri: 5 helpful answers in groups (no links), 8 new admin messages (Varyant 5), follow-ups due, partner questions, check partner posts for #işbirliği.
A30: W9 | B30: 46377 | C30: Ekin | D30: Holiday, light | E30: 8 contacts | F30: Daily ~3 h Mon–Fri: 3 X replies/quotes, 3 new messages (Varyant 6), 2 Shorts/clips a week from tutorials.
A31: W9 | B31: 46377 | C31: Weekly | D31: Mon: pick contacts · Fri: KPI report (Dashboard) to orchestrator | F31: Merisa fills Dashboard yellow cells on Friday from /admin/partners.
A32: W10 | B32: 46384 | C32: Merisa | D32: Holiday, light | E32: 20 contacts; 95 activated | F32: First partner payout run on 5 Jan (dry run first). Daily ~4 h Mon–Fri: 5 helpful answers in groups (no links), 8 new admin messages (Varyant 5), follow-ups due, partner questions, check partner posts for #işbirliği.
A33: W10 | B33: 46384 | C33: Ekin | D33: Holiday, light | E33: 8 contacts | F33: Daily ~3 h Mon–Fri: 3 X replies/quotes, 3 new messages (Varyant 6), 2 Shorts/clips a week from tutorials.
A34: W10 | B34: 46384 | C34: Weekly | D34: Mon: pick contacts · Fri: KPI report (Dashboard) to orchestrator | F34: Merisa fills Dashboard yellow cells on Friday from /admin/partners.
A35: W11 | B35: 46391 | C35: Merisa | D35: Gate review | E35: 100 activated, ≥5 paying | F35: Weekly KPI report = gate report to orchestrator/Atilla. Daily ~4 h Mon–Fri: 5 helpful answers in groups (no links), 8 new admin messages (Varyant 5), follow-ups due, partner questions, check partner posts for #işbirliği.
A36: W11 | B36: 46391 | C36: Ekin | D36: Gate review | E36: 15 contacts | F36: If gate passed: plan Instagram (T23). Daily ~3 h Mon–Fri: 3 X replies/quotes, 3 new messages (Varyant 6), 2 Shorts/clips a week from tutorials.
A37: W11 | B37: 46391 | C37: Weekly | D37: Mon: pick contacts · Fri: KPI report (Dashboard) to orchestrator | F37: Merisa fills Dashboard yellow cells on Friday from /admin/partners.
A38: W12 | B38: 46398 | C38: Merisa | D38: Phase 2 (if gate passed) | E38: Meta ads test ₺15k/month per ads-playbook | F38: Run ads per playbook; partnership intros (ShipEntegra, Paraşüt/QNB).
A39: W12 | B39: 46398 | C39: Ekin | D39: Phase 2: Instagram | E39: 3 posts/week + reels | F39: Instagram from calendar-30d.md.
A40: W12 | B40: 46398 | C40: Weekly | D40: Mon: pick contacts · Fri: KPI report (Dashboard) to orchestrator | F40: Merisa fills Dashboard yellow cells on Friday from /admin/partners.
A41: W13 | B41: 46405 | C41: Merisa | D41: Phase 2 | E41: Google Search test ₺3–5k | F41: Valentine's/Mother's Day listing-prep content via partners.
...

Sheet Content calendar
A1: Content calendar
A2: Blog rows come from docs/gtm/seo/content-calendar.md (drafted by Claude gtm-overhaul, fact-checked by Merisa). Channel / Owner / Status are dropdowns.
A4: Date | B4: Channel | C4: Title / topic | D4: Primary keyword | E4: Links to | F4: Owner | G4: Fact-check | H4: Status | I4: Published link | J4: Notes
A5: 46329 | B5: Blog | C5: Black Friday ve Cyber Monday 2026: Etsy'de indirimi kârı eritmeden kurmak | D5: etsy black friday indirimi | E5: https://kolayxport.com/cozumler/etsy-satici | F5: Claude: gtm-overhaul | G5: Merisa | H5: Draft
A6: 46331 | B6: Blog | C6: Yılbaşı teslimatı için ABD ve Avrupa'ya son gönderim tarihleri (2026) | D6: yılbaşı yurtdışı kargo son gönderim tarihi | E6: https://kolayxport.com/cozumler/mikro-ihracat-kargo-etgb | F6: Claude: gtm-overhaul | G6: Merisa | H6: Draft
A7: 46336 | B7: Blog | C7: Tatil sezonu ilanı: başlıkta "gift" ve "Christmas" ne zaman yazılır? | D7: etsy hediye ilanı nasıl yazılır | E7: https://kolayxport.com/cozumler/ai-ilan-optimizasyonu | F7: Claude: gtm-overhaul | G7: Merisa | H7: Draft
A8: 46338 | B8: Blog | C8: ABD'ye gönderide DDP mi DDU mu? De minimis sonrası karar rehberi | D8: ddp gönderim | E8: https://kolayxport.com/blog/mikro-ihracat-rehberi-2026 | F8: Claude: gtm-overhaul | G8: Merisa | H8: Draft
A9: 46343 | B9: Blog | C9: HS kodu (GTİP) nasıl bulunur? Yanlış kodun yurt dışı gönderide maliyeti | D9: hs kodu nasıl bulunur | E9: https://kolayxport.com/entegrasyonlar/fedex | F9: Claude: gtm-overhaul | G9: Merisa | H9: Draft
A10: 46345 | B10: Blog | C10: Etsy Ads ve Offsite Ads: sezon öncesi reklam bütçesini kâra göre ayarlamak | D10: etsy reklam nasıl verilir | E10: https://kolayxport.com/blog/etsy-kar-hesaplama | F10: Claude: gtm-overhaul | G10: Merisa | H10: Draft
A11: 46350 | B11: Blog | C11: Black Friday haftası: toplu etiket, toplama listesi ve paketleme fişi | D11: toplu kargo etiketi | E11: https://kolayxport.com/cozumler/mikro-ihracat-kargo-etgb | F11: Claude: gtm-overhaul | G11: Merisa | H11: Draft
A12: 46352 | B12: Blog | C12: eBay'de tatil sezonu: ilan, kargo süresi ve fiyat kontrolü | D12: ebay satış arttırma | E12: https://kolayxport.com/cozumler/ebay-satici | F12: Claude: gtm-overhaul | G12: Merisa | H12: Draft
A13: 46357 | B13: Blog | C13: Cyber Week bitti: pazaryeri bazında gerçek net kârınızı çıkarın | D13: pazaryeri kar marjı hesaplama | E13: https://kolayxport.com/nasil-kullanirim/kar-raporu | F13: Claude: gtm-overhaul | G13: Merisa | H13: Draft
A14: 46359 | B14: Blog | C14: "Teslim edildi ama gelmedi": yurt dışı gönderide kanıt ve önlem | D14: kargo teslim edildi görünüyor ama gelmedi | E14: https://kolayxport.com/entegrasyonlar/ups | F14: Claude: gtm-overhaul | G14: Merisa | H14: Draft
A15: 46364 | B15: Blog | C15: AB'ye satışta 2026 kuralları: €3 gümrük, IOSS ve KDV | D15: ioss türkiye | E15: https://kolayxport.com/blog/mikro-ihracat-rehberi-2026 | F15: Claude: gtm-overhaul | G15: Merisa | H15: Draft
A16: 46366 | B16: Blog | C16: Etsy ürün fotoğrafı: boyut, 20 görsel ve 1 video | D16: etsy ürün fotoğrafı boyutu | E16: https://kolayxport.com/cozumler/ai-ilan-optimizasyonu | F16: Claude: gtm-overhaul | G16: Merisa | H16: Draft
... A30: 46415 | B30: Blog | C30: Q1 planı: Anneler Günü (UK 7 Mart, ABD 9 Mayıs) için ilan ve stok | D30: etsy anneler günü ürünleri | E30: https://kolayxport.com/cozumler/urun-arastirma-arbitraj | F30: Claude: gtm-overhaul | G30: Merisa | H30: Draft
A31: 46328 | B31: YouTube | C31: Tutorial: etsy-baglama | E31: https://kolayxport.com/nasil-kullanirim/etsy-baglama | F31: Claude: gtm-overhaul | H31: Scheduled | J31: Unlisted now; goes Public after Atilla's OK (T08). Some guide slugs differ; check the link
A32: 46328 | B32: YouTube | C32: Tutorial: ai-ilan-optimizasyonu | E32: https://kolayxport.com/nasil-kullanirim/ai-ilan-optimizasyonu | F32: Claude: gtm-overhaul | H32: Scheduled | J32: Unlisted now; goes Public after Atilla's OK (T08). Some guide slugs differ; check the link
A33: 46328 | B33: YouTube | C33: Tutorial: ai-urun-fotografi | E33: https://kolayxport.com/nasil-kullanirim/ai-urun-fotografi | F33: Claude: gtm-overhaul | H33: Scheduled | J33: Unlisted now; goes Public after Atilla's OK (T08). Some guide slugs differ; check the link
A34: 46328 | B34: YouTube | C34: Tutorial: ai-urun-videosu | E34: https://kolayxport.com/nasil-kullanirim/ai-urun-videosu | F34: Claude: gtm-overhaul | H34: Scheduled | J34: Unlisted now; goes Public after Atilla's OK (T08). Some guide slugs differ; check the link
A35: 46328 | B35: YouTube | C35: Tutorial: etsy-ilan-olusturma | E35: https://kolayxport.com/nasil-kullanirim/etsy-ilan-olusturma | F35: Claude: gtm-overhaul | H35: Scheduled | J35: Unlisted now; goes Public after Atilla's OK (T08). Some guide slugs differ; check the link
A36: 46328 | B36: YouTube | C36: Tutorial: ebay-ilan-olusturma | E36: https://kolayxport.com/nasil-kullanirim/ebay-ilan-olusturma | F36: Claude: gtm-overhaul | H36: Scheduled | J36: Unlisted now; goes Public after Atilla's OK (T08). Some guide slugs differ; check the link
A37: 46328 | B37: YouTube | C37: Tutorial: toplu-duzenleme | E37: https://kolayxport.com/nasil-kullanirim/toplu-duzenleme | F37: Claude: gtm-overhaul | H37: Scheduled | J37: Unlisted now; goes Public after Atilla's OK (T08). Some guide slugs differ; check the link
A38: 46328 | B38: YouTube | C38: Tutorial: anahtar-kelime-arastirmasi | E38: https://kolayxport.com/nasil-kullanirim/anahtar-kelime-arastirmasi | F38: Claude: gtm-overhaul | H38: Scheduled | J38: Unlisted now; goes Public after Atilla's OK (T08). Some guide slugs differ; check the link
A39: 46328 | B39: YouTube | C39: Tutorial: arbitraj-taramasi | E39: https://kolayxport.com/nasil-kullanirim/arbitraj-taramasi | F39: Claude: gtm-overhaul | H39: Scheduled | J39: Unlisted now; goes Public after Atilla's OK (T08). Some guide slugs differ; check the link
A40: 46328 | B40: YouTube | C40: Tutorial: chrome-eklentisi | E40: https://kolayxport.com/nasil-kullanirim/chrome-eklentisi | F40: Claude: gtm-overhaul | H40: Scheduled | J40: Unlisted now; goes Public after Atilla's OK (T08). Some guide slugs differ; check the link
A41: 46328 | B41: YouTube | C41: Tutorial: etgb-ve-e-arsiv | E41: https://kolayxport.com/nasil-kullanirim/etgb-ve-e-arsiv | F41: Claude: gtm-overhaul | H41: Scheduled | J41: Unlisted now; goes Public after Atilla's OK (T08). Some guide slugs differ; check the link
A42: 46328 | B42: YouTube | C42: Tutorial: kar-raporu | E42: https://kolayxport.com/nasil-kullanirim/kar-raporu | F42: Claude: gtm-overhaul | H42: Scheduled | J42: Unlisted now; goes Public after Atilla's OK (T08). Some guide slugs differ; check the link
... A45: 46328 | B45: YouTube | C45: Tutorial: stok-senkronu | E45: https://kolayxport.com/nasil-kullanirim/stok-senkronu | F45: Claude: gtm-overhaul | H45: Scheduled | J45: Unlisted now; goes Public after Atilla's OK (T08). Some guide slugs differ; check the link

Sheet Tests QA
A1: Tests / QA
A2: Test on production (kolayxport.com) with a test e-mail, on a phone and a laptop. Never use real customer data or the protected review accounts (review@, play-review@, mcp-review@). Result / Tester are dropdowns.
A4: ID | B4: Feature | C4: Steps | D4: Expected | E4: Device | F4: Result | G4: Tester | H4: Date | I4: Bug / link | J4: Notes
A5: Q01 | B5: Referral Stage A: partner link | C5: 1) Private window → kolayxport.com/?ref=TEST-PARTNER 2) Sign up with a test e-mail 3) Open /admin/partners | D5: Report shows 1 signup for TEST-PARTNER; delete test user + partner after | E5: Laptop | F5: Not run
A6: Q02 | B6: Referral: Google sign-in via partner link | C6: 1) Private window → /?ref=TEST-PARTNER 2) Sign up with Google (test account) 3) /admin/partners | D6: Signup attributed (via 'claim') | E6: Phone | F6: Not run
A7: Q03 | B7: Signup + 14-day trial | C7: 1) /login?mode=signup 2) Sign up 3) Verify e-mail 4) Check plan/trial in settings | D7: Trial shows 14 days; no card asked | E7: Phone | F7: Not run
A8: Q04 | B8: Google / Apple first sign-in | C8: Sign in with a new Google account | D8: Lands in the app (no bounce back to /login; fixed in 1b04d991) | E8: Phone | F8: Not run
A9: Q05 | B9: Cookie panel | C9: 1) Fresh browser → 'Yalnızca zorunlu' 2) DevTools network | D9: No requests to facebook.com / google-analytics.com | E9: Laptop | F9: Not run
A10: Q06 | B10: Connect Etsy | C10: Settings › Connections › Etsy → OAuth | D10: Store connected; listings load | E10: Laptop | F10: Not run
A11: Q07 | B11: Listing doctor (onboarding hook) | C11: Open the weakest listing → Listing doctor → apply one fix → send | D11: SEO score + fixes; change stays draft until 'Gönder' | E11: Laptop | F11: Not run
A12: Q08 | B12: Chrome extension from Web Store | C12: Install from chromewebstore.google.com/detail/fjlfihofjojemlofkfejikgdbjemncba → open an Etsy search | D12: Overlay shows plain-Turkish numbers | E12: Laptop | F12: Not run
A13: Q09 | B13: Founding offer counter | C13: Open /fiyatlandirma | D13: Counter shows; never a hardcoded number in copy | E13: Phone | F13: Not run
A14: Q10 | B14: Partner promo code at checkout | C14: After founding spots are full: checkout with the partner code | D14: Discount applied; signup attributed via 'promo' | E14: Laptop | F14: Not run
A15: Q11 | B15: Tutorials embedded on guides | C15: Open 3 guide pages under /nasil-kullanirim | D15: Video plays; links in description work | E15: Phone | F15: Not run
A16: Q12 | B16: Partner dashboard /app/ortaklik (after Stage B) | C16: Log in as a test partner → /app/ortaklik | D16: Own referrals only, masked; no e-mails | E16: Phone | F16: Not run
... A18: Q14 | B18: Shopify-connected account hides referral/prices | C18: Log in to a Shopify-installed test store account | D18: No /app/ortaklik, no prices or upgrades | E18: Laptop | F18: Not run

Sheet Links
A1: Links
A2: GitHub links need repo access (ask Atilla). Stripe, YouTube Studio and the Hetzner server are Atilla-only.
A4: Category | B4: Name | C4: URL / path | D4: Who uses it | E4: Notes
A5: Plan | B5: Turkey gameplan | C5: https://github.com/bloodyteeths/kolayxport_supa/blob/main/docs/gtm/turkey-gameplan.md | D5: Everyone | E5: Phase 1/2, weekly targets, templates (§4.5)
A6: Plan | B6: Pricing v2 (proposal) | C6: https://github.com/bloodyteeths/kolayxport_supa/blob/main/docs/gtm/pricing-v2.md | D6: Atilla
A7: Plan | B7: Referral build spec | C7: https://github.com/bloodyteeths/kolayxport_supa/blob/main/docs/gtm/referral-spec.md | D7: Claude d7
A8: Plan | B8: GTM handbook (marketing README) | C8: https://github.com/bloodyteeths/kolayxport_supa/blob/main/docs/gtm/README.md | D8: Merisa, Ekin | E8: Claims rules, weekly routine
A9: Plan | B9: Feature inventory (only source for claims) | C9: https://github.com/bloodyteeths/kolayxport_supa/blob/main/docs/gtm/feature-inventory.md | D9: Merisa, Ekin | E9: §4 = never claim
A10: Templates | B10: Outreach messages (Varyant 1–4 + follow-ups) | C10: https://github.com/bloodyteeths/kolayxport_supa/blob/main/docs/gtm/social/outreach-messages.md | D10: Merisa, Ekin | E10: Partner Varyant 5/6 are in gameplan §4.5
A11: Templates | B11: Social kit + claims cheat sheet | C11: https://github.com/bloodyteeths/kolayxport_supa/blob/main/docs/gtm/social/README.md | D11: Merisa, Ekin
A12: Templates | B12: 30-day social calendar | C12: https://github.com/bloodyteeths/kolayxport_supa/blob/main/docs/gtm/social/calendar-30d.md | D12: Ekin | E12: Phase 2 Instagram
A13: Templates | B13: Ads playbook | C13: https://github.com/bloodyteeths/kolayxport_supa/blob/main/docs/gtm/social/ads-playbook.md | D13: Merisa | E13: Phase 2 only
A14: Templates | B14: Legal notes (İYS, #işbirliği, KVKK) | C14: https://github.com/bloodyteeths/kolayxport_supa/blob/main/docs/gtm/social/legal-notes.md | D14: Merisa, Ekin
A15: Templates | B15: Communities list | C15: https://github.com/bloodyteeths/kolayxport_supa/blob/main/docs/gtm/social/communities.csv | D15: Merisa, Ekin
A16: Templates | B16: Blog content calendar | C16: https://github.com/bloodyteeths/kolayxport_supa/blob/main/docs/gtm/seo/content-calendar.md | D16: Merisa
A17: App | B17: Admin: partners report | C17: https://kolayxport.com/admin/partners | D17: Atilla, Merisa (admin role) | E17: Signups / activated / paying per partner
A18: App | B18: Partner dashboard (after Stage B) | C18: https://kolayxport.com/app/ortaklik | D18: Partners
A19: App | B19: Pricing page | C19: https://kolayxport.com/fiyatlandirma | D19: Everyone
A20: App | B20: Signup | C20: https://kolayxport.com/login?mode=signup | D20: Everyone
A21: App | B21: Use-case pages (ad/partner landing) | C21: https://kolayxport.com/cozumler | D21: Merisa, Ekin | E21: etsy-satici, ebay-satici, ai-ilan-optimizasyonu, mikro-ihracat-kargo-etgb, trendyoldan-dunyaya, urun-arastirma-arbitraj
A22: App | B22: How-to guides | C22: https://kolayxport.com/nasil-kullanirim | D22: Everyone
A23: App | B23: Health check | C23: https://kolayxport.com/api/health | D23: Atilla
A24: External | B24: Chrome extension (Web Store) | C24: https://chromewebstore.google.com/detail/fjlfihofjojemlofkfejikgdbjemncba | D24: Everyone
A25: External | B25: Extension promo video | C25: https://youtu.be/RtHJlVkvAqg | D25: Merisa, Ekin
A26: External | B26: YouTube Studio | C26: https://studio.youtube.com | D26: Atilla
A27: External | B27: Stripe dashboard (Tamsar, Inc.) | C27: https://dashboard.stripe.com | D27: Atilla | E27: Coupons, promo codes, Global Payouts
A28: External | B28: Reklam Kurulu influencer guide (send to partners) | C28: https://ticaret.gov.tr/haberler/ticaret-bakanligi-sosyal-medya-etkileyicileri-icin-kilavuz-yayimladi | D28: Merisa, Ekin
A29: External | B29: Bionluk (freelancers) | C29: https://bionluk.com | D29: Merisa
A30: External | B30: PraPazar packages (pricing reference) | C30: https://prapazar.com/tr/paketler | D30: Atilla | E30: Checked 2026-10-19

Sheet Decisions log
A1: Decisions log
A2: Append only: new decisions at the bottom, never edit old rows (add a new row that supersedes them).
A4: Date | B4: Decision | C4: Decided by | D4: Source | E4: Supersedes / notes
A5: 46309 | B5: Prices Starter ₺2.499 / Growth ₺4.999 / Pro ₺7.999 a month, 14-day no-card trial, founding 40% off for life for the first 20 | C5: Atilla | D5: memory: pricing strategy | E5: Superseded by pricing v2 (2026-10-19) for Turkey
A6: 46312 | B6: Positioning A + C: 'Yurt dışına satışın tek paneli' + 'Trendyol'dan dünyaya' track; domestic features only as supporting proof | C6: Atilla | D6: docs/gtm/positioning.md
A7: 46314 | B7: No free tier: entry is the 14-day trial + founding offer | C7: Atilla | D7: turkey-gameplan §0
A8: 46314 | B8: GTM cash cap ₺25.000/month; no ad spend until 100 activated users (Phase 1 = referral partners) | C8: Atilla | D8: turkey-gameplan §0, §4.9
A9: 46314 | B9: Merisa and Ekin run marketing; Atilla stays out of day-to-day | C9: Atilla | D9: orchestrator
A10: 46314 | B10: Ekin ~15 h/week on KolayXport (30 h split with the Amazon shop) | C10: Atilla | D10: orchestrator
A11: 46314 | B11: Prices shown '+KDV' with the total at checkout | C11: Orchestrator for Atilla | D11: turkey-gameplan §0 | E11: Accountant to confirm (pricing-v2 §5)
A12: 46314 | B12: Partner code after founding spots: 20% off (first yearly payment / first 3 months of Aylık) | C12: Orchestrator for Atilla | D12: turkey-gameplan §2
A13: 46314 | B13: Pricing v2 model: yearly packages main offer, ONE monthly plan (Aylık) + modules; iyzico/PayTR for taksit | C13: Atilla | D13: docs/gtm/pricing-v2.md | E13: Numbers still a proposal (T05)
A14: 46314 | B14: Partner bounty one-time: 25% of the first yearly payment (30% from the 10th paying referral); ₺1.500 for Aylık after the 2nd payment | C14: Atilla | D14: turkey-gameplan §4.2 | E14: Supersedes 30% recurring for 12 months (same day)
A15: 46314 | B15: Partner dashboard in the app with masked referrals; payouts via Stripe Global Payouts | C15: Atilla | D15: referral-spec §4 | E15: Paying entity depends on accountant (T07)
A16: 46314 | B16: Pricing v2 prices CONFIRMED: Başlangıç ₺29.990, Büyüme ₺54.990, Pro ₺89.990, Kurumsal from ₺149.990 a year; Aylık ₺2.999 a month; all +KDV. Module prices still a proposal; partners quote no prices until checkout exists | C16: Atilla | D16: command board 19 Oct 19:48 (via orchestrator) | E16: Seller of record / KDV still with the accountant
A17: 46314 | B17: Payments collected by Tamsar, Inc. (US) in TRY under its agreement with Modsons | C17: Atilla | D17: pricing-v2 §1 | E17: Proposal: Modsons sells to Turkish customers; open with the accountant
A18: 46314 | B18: Cookie panel is live (since 2026-10-17); only tracking IDs gate Phase 2 measurement | C18: gtm-overhaul (verified) | D18: turkey-gameplan §4.9

Sheet Lists
A1: Owners | B1: TaskStatus | C1: Priority | D1: PartnerType | E1: Channel | F1: PartnerStatus | G1: YesNo | H1: ContentChannel | I1: ContentStatus | J1: TestResult | K1: Testers | L1: PartnerOwners
A2: Atilla | B2: Not started | C2: P0 | D2: fb_admin | E2: Facebook | F2: Shortlisted | G2: Yes | H2: Blog | I2: Idea | J2: Not run | K2: Merisa | L2: Merisa
A3: Merisa | B3: In progress | C3: P1 | D3: tg_admin | E3: Telegram | F3: Contacted | G3: No | H3: YouTube | I3: Draft | J3: Pass | K3: Ekin | L3: Ekin
A4: Ekin | B4: Waiting | C4: P2 | D4: x_voice | E4: WhatsApp | F4: Replied | H4: Shorts/Reels | I4: In review | J4: Fail | K4: Atilla
